Workbook
Name Slicer_Branch: #N/A
Name Slicer_Industry: #N/A
Name Slicer_Internship: #N/A
Name Slicer_Skill: #N/A

Sheet PivotSheets
A1: Placement By Branch
A3: Branch | B3: Count of Student_ID | C3: Sum of Placement Indicator | D3: Placement Rate
A4: Civil | B4: 45 | C4: 30 | D4: =C4/B4 -> 0.66666667
A5: CSE | B5: 136 | C5: 94 | D5: =C5/B5 -> 0.69117647
A6: ECE | B6: 80 | C6: 52 | D6: =C6/B6 -> 0.65
A7: EE | B7: 60 | C7: 39 | D7: =C7/B7 -> 0.65
A8: IT | B8: 98 | C8: 68 | D8: =C8/B8 -> 0.69387755
A9: MBA | B9: 16 | C9: 10 | D9: =C9/B9 -> 0.625
A10: Mechanical | B10: 65 | C10: 32 | D10: =C10/B10 -> 0.49230769
A11: Grand Total | B11: 500 | C11: 325
A15: Internship Impact
A17: Internship Status | B17: Count of Student_ID | C17: Sum of Placement Indicator | D17: placement%
A18: No | B18: 208 | C18: 116 | D18: =C18/B18 -> 0.55769231
A19: Yes | B19: 292 | C19: 209 | D19: =C19/B19 -> 0.71575342
A20: Grand Total | B20: 500 | C20: 325 | D20: =C20/B20 -> 0.65
A23: Skill Analysis
A25: Skill | B25: Average of Package_LPA | C25: Count of Student_ID
A26: ANSYS | B26: 5.6352941 | C26: 17
A27: AutoCAD | B27: 3.4 | C27: 9
A28: AutoCAD Electrical | B28: 5.35 | C28: 4
A29: Business Analytics | B29: 6.1 | C29: 1
A30: C | B30: 8.1142857 | C30: 7
A31: CATIA | B31: 7.7 | C31: 6
A32: Cloud Basics | B32: 7.5363636 | C32: 11
A33: Data Analytics | B33: 9.6444444 | C33: 27
A34: Digital Electronics | B34: 6.375 | C34: 8
A35: Embedded Systems | B35: 11.8 | C35: 8
A36: Estimation | B36: 8.1 | C36: 8
A37: Excel | B37: 7.7546875 | C37: 64
... A63: Grand Total | B63: 7.8998 | C63: 500
A66: Branch vs Average Package
A68: Branch | B68: Average of Package_LPA
A69: Civil | B69: 6.3466667
A70: CSE | B70: 8.7022059
A71: ECE | B71: 8.24125
A72: EE | B72: 7.5866667
A73: IT | B73: 9.0255102
A74: MBA | B74: 8.93125
A75: Mechanical | B75: 5.2138462
A76: Grand Total | B76: 7.8998
...

Sheet Charts
A1: Branch | B1: Placement%
A2: =PivotSheets!A4 -> Civil | B2: =PivotSheets!D4 -> 0.66666667
A3: =PivotSheets!A5 -> CSE | B3: =PivotSheets!D5 -> 0.69117647
A4: =PivotSheets!A6 -> ECE | B4: =PivotSheets!D6 -> 0.65
A5: =PivotSheets!A7 -> EE | B5: =PivotSheets!D7 -> 0.65
A6: =PivotSheets!A8 -> IT | B6: =PivotSheets!D8 -> 0.69387755
A7: =PivotSheets!A9 -> MBA | B7: =PivotSheets!D9 -> 0.625
A8: =PivotSheets!A10 -> Mechanical | B8: =PivotSheets!D10 -> 0.49230769
A15: Skill | B15: Average_Package
A16: =PivotSheets!A27 -> AutoCAD | B16: =PivotSheets!B27 -> 3.4
A17: =PivotSheets!A49 -> Project Planning | B17: =PivotSheets!B49 -> 3.75
A18: =PivotSheets!A51 -> Quality Control | B18: =PivotSheets!B51 -> 4.0222222
A19: =PivotSheets!A52 -> Quantity Surveying | B19: =PivotSheets!B52 -> 4.0666667
A20: =PivotSheets!A39 -> HR Analytics | B20: =PivotSheets!B39 -> 4.5
A21: =PivotSheets!A62 -> Web Development | B21: =PivotSheets!B62 -> 4.8
A22: =PivotSheets!A43 -> Manufacturing | B22: =PivotSheets!B43 -> 4.9888889
A23: =PivotSheets!A28 -> AutoCAD Electrical | B23: =PivotSheets!B28 -> 5.35
A24: =PivotSheets!A58 -> STAAD Pro | B24: =PivotSheets!B58 -> 5.5333333
A25: =PivotSheets!A53 -> Renewable Energy | B25: =PivotSheets!B53 -> 5.5636364
A26: =PivotSheets!A26 -> ANSYS | B26: =PivotSheets!B26 -> 5.6352941
A27: =PivotSheets!A44 -> MATLAB | B27: =PivotSheets!B44 -> 5.824
A28: =PivotSheets!A29 -> Business Analytics | B28: =PivotSheets!B29 -> 6.1
A29: =PivotSheets!A42 -> Machine Learning | B29: =PivotSheets!B42 -> 6.3384615
A30: =PivotSheets!A34 -> Digital Electronics | B30: =PivotSheets!B34 -> 6.375
A31: =PivotSheets!A55 -> SCADA | B31: =PivotSheets!B55 -> 6.65
A32: =PivotSheets!A45 -> PLC | B32: =PivotSheets!B45 -> 6.92
A33: =PivotSheets!A48 -> Presentation Skills | B33: =PivotSheets!B48 -> 6.94
A34: =PivotSheets!A32 -> Cloud Basics | B34: =PivotSheets!B32 -> 7.5363636
A35: =PivotSheets!A59 -> Surveying | B35: =PivotSheets!B59 -> 7.65
A36: =PivotSheets!A31 -> CATIA | B36: =PivotSheets!B31 -> 7.7
A37: =PivotSheets!A37 -> Excel | B37: =PivotSheets!B37 -> 7.7546875
A38: =PivotSheets!A41 -> Java | B38: =PivotSheets!B41 -> 8
A39: =PivotSheets!A61 -> VLSI | B39: =PivotSheets!B61 -> 8.09
A40: =PivotSheets!A36 -> Estimation | B40: =PivotSheets!B36 -> 8.1
A41: =PivotSheets!A30 -> C | B41: =PivotSheets!B30 -> 8.1142857
A42: =PivotSheets!A54 -> Revit | B42: =PivotSheets!B54 -> 8.2714286
A43: =PivotSheets!A47 -> Power Systems | B43: =PivotSheets!B47 -> 8.54
A44: =PivotSheets!A57 -> SQL | B44: =PivotSheets!B57 -> 8.8394737
A45: =PivotSheets!A50 -> Python | B45: =PivotSheets!B50 -> 9.64375
A46: =PivotSheets!A33 -> Data Analytics | B46: =PivotSheets!B33 -> 9.6444444
...

Sheet Dashboard
A1: =KPI_Calculations!B1 -> 500 | E1: =KPI_Calculations!B3 -> 0.65 | I1: =KPI_Calculations!B4 -> 7.8998 | M1: =KPI_Calculations!B5 -> 24.4 | Q1: =KPI_Calculations!B6 -> 45
A4: Total Students | E4: Placement % | I4: Average Package(LPA) | M4: Highest Package | Q4: Total Recruiters
AC20: +

Sheet Placement_Data
A1: Student_ID | B1: Branch | C1: CGPA | D1: Internship | E1: Skill | F1: Placement_Status | G1: Package_LPA | H1: Company | I1: Industry | J1: Student_ID | K1: Placement Indicator | L1: CGPA Group | M1: Package Category | N1: Internship Indicator | P1: Unique Companies
A2: S001 | B2: EE | C2: 5.3 | D2: Yes | E2: Power Systems | F2: Placed | G2: 11 | H2: Schneider Electric | I2: Electrical | J2: S001 | K2: =IF(tblPlacement[Placement_Status]="Placed",1,0) -> 1 | L2: =IF(tblPlacement[CGPA]>=9,"9+", IF(tblPlacement[CGPA]>=8,"8-9",IF(tblPlacement[CGPA]>=7,"7-8","Below 7"))) -> Below 7 | M2: =IF(tblPlacement[Package_LPA]>=15,"High",IF(tblPlacement[Package_LPA]>=8,"Medium","Low")) -> Medium | N2: =IF(tblPlacement[Internship]="Yes",1,0) -> 1 | P2: Schneider Electric
A3: S002 | B3: CSE | C3: 5.6 | D3: Yes | E3: Python | F3: Placed | G3: 11.2 | H3: Wipro | I3: IT | J3: S002 | K3: =IF(tblPlacement[Placement_Status]="Placed",1,0) -> 1 | L3: =IF(tblPlacement[CGPA]>=9,"9+", IF(tblPlacement[CGPA]>=8,"8-9",IF(tblPlacement[CGPA]>=7,"7-8","Below 7"))) -> Below 7 | M3: =IF(tblPlacement[Package_LPA]>=15,"High",IF(tblPlacement[Package_LPA]>=8,"Medium","Low")) -> Medium | N3: =IF(tblPlacement[Internship]="Yes",1,0) -> 1 | P3: Wipro
A4: S003 | B4: CSE | C4: 9.2 | D4: No | E4: SQL | F4: Placed | G4: 6.7 | H4: Cognizant | I4: IT | J4: S003 | K4: =IF(tblPlacement[Placement_Status]="Placed",1,0) -> 1 | L4: =IF(tblPlacement[CGPA]>=9,"9+", IF(tblPlacement[CGPA]>=8,"8-9",IF(tblPlacement[CGPA]>=7,"7-8","Below 7"))) -> 9+ | M4: =IF(tblPlacement[Package_LPA]>=15,"High",IF(tblPlacement[Package_LPA]>=8,"Medium","Low")) -> Low | N4: =IF(tblPlacement[Internship]="Yes",1,0) -> 0 | P4: Cognizant
A5: S004 | B5: Civil | C5: 6.7 | D5: Yes | E5: STAAD Pro | F5: Placed | G5: 10.8 | H5: L&T Construction | I5: Civil | J5: S004 | K5: =IF(tblPlacement[Placement_Status]="Placed",1,0) -> 1 | L5: =IF(tblPlacement[CGPA]>=9,"9+", IF(tblPlacement[CGPA]>=8,"8-9",IF(tblPlacement[CGPA]>=7,"7-8","Below 7"))) -> Below 7 | M5: =IF(tblPlacement[Package_LPA]>=15,"High",IF(tblPlacement[Package_LPA]>=8,"Medium","Low")) -> Medium | N5: =IF(tblPlacement[Internship]="Yes",1,0) -> 1 | P5: L&T Construction
A6: S005 | B6: ECE | C6: 9.7 | D6: Yes | E6: C | F6: Not Placed | G6: 0 | H6: NA | I6: NA | J6: S005 | K6: =IF(tblPlacement[Placement_Status]="Placed",1,0) -> 0 | L6: =IF(tblPlacement[CGPA]>=9,"9+", IF(tblPlacement[CGPA]>=8,"8-9",IF(tblPlacement[CGPA]>=7,"7-8","Below 7"))) -> 9+ | M6: =IF(tblPlacement[Package_LPA]>=15,"High",IF(tblPlacement[Package_LPA]>=8,"Medium","Low")) -> Low | N6: =IF(tblPlacement[Internship]="Yes",1,0) -> 1 | O6: NA | P6: NA
A7: S006 | B7: ECE | C7: 9.2 | D7: Yes | E7: VLSI | F7: Placed | G7: 19.1 | H7: Qualcomm | I7: Electronics | J7: S006 | K7: =IF(tblPlacement[Placement_Status]="Placed",1,0) -> 1 | L7: =IF(tblPlacement[CGPA]>=9,"9+", IF(tblPlacement[CGPA]>=8,"8-9",IF(tblPlacement[CGPA]>=7,"7-8","Below 7"))) -> 9+ | M7: =IF(tblPlacement[Package_LPA]>=15,"High",IF(tblPlacement[Package_LPA]>=8,"Medium","Low")) -> High | N7: =IF(tblPlacement[Internship]="Yes",1,0) -> 1 | P7: Qualcomm
A8: S007 | B8: IT | C8: 7.3 | D8: No | E8: Excel | F8: Placed | G8: 14.5 | H8: Cognizant | I8: IT | J8: S007 | K8: =IF(tblPlacement[Placement_Status]="Placed",1,0) -> 1 | L8: =IF(tblPlacement[CGPA]>=9,"9+", IF(tblPlacement[CGPA]>=8,"8-9",IF(tblPlacement[CGPA]>=7,"7-8","Below 7"))) -> 7-8 | M8: =IF(tblPlacement[Package_LPA]>=15,"High",IF(tblPlacement[Package_LPA]>=8,"Medium","Low")) -> Medium | N8: =IF(tblPlacement[Internship]="Yes",1,0) -> 0 | P8: Tata Power
A9: S008 | B9: EE | C9: 5.5 | D9: No | E9: Power Systems | F9: Placed | G9: 11.5 | H9: Tata Power | I9: Electrical | J9: S008 | K9: =IF(tblPlacement[Placement_Status]="Placed",1,0) -> 1 | L9: =IF(tblPlacement[CGPA]>=9,"9+", IF(tblPlacement[CGPA]>=8,"8-9",IF(tblPlacement[CGPA]>=7,"7-8","Below 7"))) -> Below 7 | M9: =IF(tblPlacement[Package_LPA]>=15,"High",IF(tblPlacement[Package_LPA]>=8,"Medium","Low")) -> Medium | N9: =IF(tblPlacement[Internship]="Yes",1,0) -> 0 | P9: Deloitte
A10: S009 | B10: Mechanical | C10: 8.8 | D10: Yes | E10: AutoCAD | F10: Not Placed | G10: 0 | H10: NA | I10: NA | J10: S009 | K10: =IF(tblPlacement[Placement_Status]="Placed",1,0) -> 0 | L10: =IF(tblPlacement[CGPA]>=9,"9+", IF(tblPlacement[CGPA]>=8,"8-9",IF(tblPlacement[CGPA]>=7,"7-8","Below 7"))) -> 8-9 | M10: =IF(tblPlacement[Package_LPA]>=15,"High",IF(tblPlacement[Package_LPA]>=8,"Medium","Low")) -> Low | N10: =IF(tblPlacement[Internship]="Yes",1,0) -> 1 | P10: TCS
A11: S010 | B11: IT | C11: 5.5 | D11: No | E11: Java | F11: Placed | G11: 16.3 | H11: Deloitte | I11: IT | J11: S010 | K11: =IF(tblPlacement[Placement_Status]="Placed",1,0) -> 1 | L11: =IF(tblPlacement[CGPA]>=9,"9+", IF(tblPlacement[CGPA]>=8,"8-9",IF(tblPlacement[CGPA]>=7,"7-8","Below 7"))) -> Below 7 | M11: =IF(tblPlacement[Package_LPA]>=15,"High",IF(tblPlacement[Package_LPA]>=8,"Medium","Low")) -> High | N11: =IF(tblPlacement[Internship]="Yes",1,0) -> 0 | P11: IBM
A12: S011 | B12: EE | C12: 5.9 | D12: Yes | E12: AutoCAD Electrical | F12: Not Placed | G12: 0 | H12: NA | I12: NA | J12: S011 | K12: =IF(tblPlacement[Placement_Status]="Placed",1,0) -> 0 | L12: =IF(tblPlacement[CGPA]>=9,"9+", IF(tblPlacement[CGPA]>=8,"8-9",IF(tblPlacement[CGPA]>=7,"7-8","Below 7"))) -> Below 7 | M12: =IF(tblPlacement[Package_LPA]>=15,"High",IF(tblPlacement[Package_LPA]>=8,"Medium","Low")) -> Low | N12: =IF(tblPlacement[Internship]="Yes",1,0) -> 1 | P12: Bosch
A13: S012 | B13: IT | C13: 7.9 | D13: Yes | E13: Excel | F13: Placed | G13: 18 | H13: TCS | I13: IT | J13: S012 | K13: =IF(tblPlacement[Placement_Status]="Placed",1,0) -> 1 | L13: =IF(tblPlacement[CGPA]>=9,"9+", IF(tblPlacement[CGPA]>=8,"8-9",IF(tblPlacement[CGPA]>=7,"7-8","Below 7"))) -> 7-8 | M13: =IF(tblPlacement[Package_LPA]>=15,"High",IF(tblPlacement[Package_LPA]>=8,"Medium","Low")) -> High | N13: =IF(tblPlacement[Internship]="Yes",1,0) -> 1 | P13: Sony
A14: S013 | B14: CSE | C14: 5.9 | D14: No | E14: Java | F14: Placed | G14: 7.1 | H14: IBM | I14: IT | J14: S013 | K14: =IF(tblPlacement[Placement_Status]="Placed",1,0) -> 1 | L14: =IF(tblPlacement[CGPA]>=9,"9+", IF(tblPlacement[CGPA]>=8,"8-9",IF(tblPlacement[CGPA]>=7,"7-8","Below 7"))) -> Below 7 | M14: =IF(tblPlacement[Package_LPA]>=15,"High",IF(tblPlacement[Package_LPA]>=8,"Medium","Low")) -> Low | N14: =IF(tblPlacement[Internship]="Yes",1,0) -> 0 | P14: Thermax
A15: S014 | B15: ECE | C15: 9.5 | D15: No | E15: VLSI | F15: Not Placed | G15: 0 | H15: NA | I15: NA | J15: S014 | K15: =IF(tblPlacement[Placement_Status]="Placed",1,0) -> 0 | L15: =IF(tblPlacement[CGPA]>=9,"9+", IF(tblPlacement[CGPA]>=8,"8-9",IF(tblPlacement[CGPA]>=7,"7-8","Below 7"))) -> 9+ | M15: =IF(tblPlacement[Package_LPA]>=15,"High",IF(tblPlacement[Package_LPA]>=8,"Medium","Low")) -> Low | N15: =IF(tblPlacement[Internship]="Yes",1,0) -> 0 | P15: Accenture
A16: S015 | B16: ECE | C16: 6.4 | D16: No | E16: VLSI | F16: Placed | G16: 16.3 | H16: Bosch | I16: Electronics | J16: S015 | K16: =IF(tblPlacement[Placement_Status]="Placed",1,0) -> 1 | L16: =IF(tblPlacement[CGPA]>=9,"9+", IF(tblPlacement[CGPA]>=8,"8-9",IF(tblPlacement[CGPA]>=7,"7-8","Below 7"))) -> Below 7 | M16: =IF(tblPlacement[Package_LPA]>=15,"High",IF(tblPlacement[Package_LPA]>=8,"Medium","Low")) -> High | N16: =IF(tblPlacement[Internship]="Yes",1,0) -> 0 | P16: Infosys
A17: S016 | B17: Mechanical | C17: 7.5 | D17: Yes | E17: Manufacturing | F17: Not Placed | G17: 0 | H17: NA | I17: NA | J17: S016 | K17: =IF(tblPlacement[Placement_Status]="Placed",1,0) -> 0 | L17: =IF(tblPlacement[CGPA]>=9,"9+", IF(tblPlacement[CGPA]>=8,"8-9",IF(tblPlacement[CGPA]>=7,"7-8","Below 7"))) -> 7-8 | M17: =IF(tblPlacement[Package_LPA]>=15,"High",IF(tblPlacement[Package_LPA]>=8,"Medium","Low")) -> Low | N17: =IF(tblPlacement[Internship]="Yes",1,0) -> 1 | P17: HCL
A18: S017 | B18: ECE | C18: 6.1 | D18: Yes | E18: MATLAB | F18: Placed | G18: 4.8 | H18: Sony | I18: Electronics | J18: S017 | K18: =IF(tblPlacement[Placement_Status]="Placed",1,0) -> 1 | L18: =IF(tblPlacement[CGPA]>=9,"9+", IF(tblPlacement[CGPA]>=8,"8-9",IF(tblPlacement[CGPA]>=7,"7-8","Below 7"))) -> Below 7 | M18: =IF(tblPlacement[Package_LPA]>=15,"High",IF(tblPlacement[Package_LPA]>=8,"Medium","Low")) -> Low | N18: =IF(tblPlacement[Internship]="Yes",1,0) -> 1 | P18: Texas Instruments
... A46: S045 | B46: CSE | C46: 8.6 | D46: Yes | E46: Power BI | F46: Placed | G46: 7.1 | H46: Cognizant | I46: IT | J46: S045 | K46: =IF(tblPlacement[Placement_Status]="Placed",1,0) -> 1 | L46: =IF(tblPlacement[CGPA]>=9,"9+", IF(tblPlacement[CGPA]>=8,"8-9",IF(tblPlacement[CGPA]>=7,"7-8","Below 7"))) -> 8-9 | M46: =IF(tblPlacement[Package_LPA]>=15,"High",IF(tblPlacement[Package_LPA]>=8,"Medium","Low")) -> Low | N46: =IF(tblPlacement[Internship]="Yes",1,0) -> 1 | P46: Punj Lloyd
A47: S046 | B47: EE | C47: 7 | D47: Yes | E47: Renewable Energy | F47: Placed | G47: 6.7 | H47: Tata Power | I47: Electrical | J47: S046 | K47: =IF(tblPlacement[Placement_Status]="Placed",1,0) -> 1 | L47: =IF(tblPlacement[CGPA]>=9,"9+", IF(tblPlacement[CGPA]>=8,"8-9",IF(tblPlacement[CGPA]>=7,"7-8","Below 7"))) -> 7-8 | M47: =IF(tblPlacement[Package_LPA]>=15,"High",IF(tblPlacement[Package_LPA]>=8,"Medium","Low")) -> Low | N47: =IF(tblPlacement[Internship]="Yes",1,0) -> 1
A48: S047 | B48: EE | C48: 7 | D48: Yes | E48: SCADA | F48: Not Placed | G48: 0 | H48: NA | I48: NA | J48: S047 | K48: =IF(tblPlacement[Placement_Status]="Placed",1,0) -> 0 | L48: =IF(tblPlacement[CGPA]>=9,"9+", IF(tblPlacement[CGPA]>=8,"8-9",IF(tblPlacement[CGPA]>=7,"7-8","Below 7"))) -> 7-8 | M48: =IF(tblPlacement[Package_LPA]>=15,"High",IF(tblPlacement[Package_LPA]>=8,"Medium","Low")) -> Low | N48: =IF(tblPlacement[Internship]="Yes",1,0) -> 1
A49: S048 | B49: CSE | C49: 8.2 | D49: Yes | E49: Excel | F49: Not Placed | G49: 0 | H49: NA | I49: NA | J49: S048 | K49: =IF(tblPlacement[Placement_Status]="Placed",1,0) -> 0 | L49: =IF(tblPlacement[CGPA]>=9,"9+", IF(tblPlacement[CGPA]>=8,"8-9",IF(tblPlacement[CGPA]>=7,"7-8","Below 7"))) -> 8-9 | M49: =IF(tblPlacement[Package_LPA]>=15,"High",IF(tblPlacement[Package_LPA]>=8,"Medium","Low")) -> Low | N49: =IF(tblPlacement[Internship]="Yes",1,0) -> 1
A50: S049 | B50: CSE | C50: 9.7 | D50: Yes | E50: Data Analytics | F50: Placed | G50: 17.9 | H50: Capgemini | I50: IT | J50: S049 | K50: =IF(tblPlacement[Placement_Status]="Placed",1,0) -> 1 | L50: =IF(tblPlacement[CGPA]>=9,"9+", IF(tblPlacement[CGPA]>=8,"8-9",IF(tblPlacement[CGPA]>=7,"7-8","Below 7"))) -> 9+ | M50: =IF(tblPlacement[Package_LPA]>=15,"High",IF(tblPlacement[Package_LPA]>=8,"Medium","Low")) -> High | N50: =IF(tblPlacement[Internship]="Yes",1,0) -> 1
A51: S050 | B51: ECE | C51: 7.6 | D51: Yes | E51: Python | F51: Placed | G51: 9.7 | H51: Texas Instruments | I51: Electronics | J51: S050 | K51: =IF(tblPlacement[Placement_Status]="Placed",1,0) -> 1 | L51: =IF(tblPlacement[CGPA]>=9,"9+", IF(tblPlacement[CGPA]>=8,"8-9",IF(tblPlacement[CGPA]>=7,"7-8","Below 7"))) -> 7-8 | M51: =IF(tblPlacement[Package_LPA]>=15,"High",IF(tblPlacement[Package_LPA]>=8,"Medium","Low")) -> Medium | N51: =IF(tblPlacement[Internship]="Yes",1,0) -> 1
A52: S051 | B52: CSE | C52: 8.3 | D52: Yes | E52: Excel | F52: Placed | G52: 12.4 | H52: Cognizant | I52: IT | J52: S051 | K52: =IF(tblPlacement[Placement_Status]="Placed",1,0) -> 1 | L52: =IF(tblPlacement[CGPA]>=9,"9+", IF(tblPlacement[CGPA]>=8,"8-9",IF(tblPlacement[CGPA]>=7,"7-8","Below 7"))) -> 8-9 | M52: =IF(tblPlacement[Package_LPA]>=15,"High",IF(tblPlacement[Package_LPA]>=8,"Medium","Low")) -> Medium | N52: =IF(tblPlacement[Internship]="Yes",1,0) -> 1
A53: S052 | B53: EE | C53: 6.7 | D53: No | E53: MATLAB | F53: Placed | G53: 11.2 | H53: ABB | I53: Electrical | J53: S052 | K53: =IF(tblPlacement[Placement_Status]="Placed",1,0) -> 1 | L53: =IF(tblPlacement[CGPA]>=9,"9+", IF(tblPlacement[CGPA]>=8,"8-9",IF(tblPlacement[CGPA]>=7,"7-8","Below 7"))) -> Below 7 | M53: =IF(tblPlacement[Package_LPA]>=15,"High",IF(tblPlacement[Package_LPA]>=8,"Medium","Low")) -> Medium | N53: =IF(tblPlacement[Internship]="Yes",1,0) -> 0
A54: S053 | B54: IT | C54: 7.7 | D54: Yes | E54: Data Analytics | F54: Placed | G54: 11.4 | H54: HCL | I54: IT | J54: S053 | K54: =IF(tblPlacement[Placement_Status]="Placed",1,0) -> 1 | L54: =IF(tblPlacement[CGPA]>=9,"9+", IF(tblPlacement[CGPA]>=8,"8-9",IF(tblPlacement[CGPA]>=7,"7-8","Below 7"))) -> 7-8 | M54: =IF(tblPlacement[Package_LPA]>=15,"High",IF(tblPlacement[Package_LPA]>=8,"Medium","Low")) -> Medium | N54: =IF(tblPlacement[Internship]="Yes",1,0) -> 1
A55: S054 | B55: EE | C55: 7.6 | D55: No | E55: MATLAB | F55: Not Placed | G55: 0 | H55: NA | I55: NA | J55: S054 | K55: =IF(tblPlacement[Placement_Status]="Placed",1,0) -> 0 | L55: =IF(tblPlacement[CGPA]>=9,"9+", IF(tblPlacement[CGPA]>=8,"8-9",IF(tblPlacement[CGPA]>=7,"7-8","Below 7"))) -> 7-8 | M55: =IF(tblPlacement[Package_LPA]>=15,"High",IF(tblPlacement[Package_LPA]>=8,"Medium","Low")) -> Low | N55: =IF(tblPlacement[Internship]="Yes",1,0) -> 0
A56: S055 | B56: IT | C56: 8.3 | D56: No | E56: SQL | F56: Not Placed | G56: 0 | H56: NA | I56: NA | J56: S055 | K56: =IF(tblPlacement[Placement_Status]="Placed",1,0) -> 0 | L56: =IF(tblPlacement[CGPA]>=9,"9+", IF(tblPlacement[CGPA]>=8,"8-9",IF(tblPlacement[CGPA]>=7,"7-8","Below 7"))) -> 8-9 | M56: =IF(tblPlacement[Package_LPA]>=15,"High",IF(tblPlacement[Package_LPA]>=8,"Medium","Low")) -> Low | N56: =IF(tblPlacement[Internship]="Yes",1,0) -> 0
A57: S056 | B57: Mechanical | C57: 8.3 | D57: Yes | E57: ANSYS | F57: Placed | G57: 10.9 | H57: L&T | I57: Mechanical | J57: S056 | K57: =IF(tblPlacement[Placement_Status]="Placed",1,0) -> 1 | L57: =IF(tblPlacement[CGPA]>=9,"9+", IF(tblPlacement[CGPA]>=8,"8-9",IF(tblPlacement[CGPA]>=7,"7-8","Below 7"))) -> 8-9 | M57: =IF(tblPlacement[Package_LPA]>=15,"High",IF(tblPlacement[Package_LPA]>=8,"Medium","Low")) -> Medium | N57: =IF(tblPlacement[Internship]="Yes",1,0) -> 1
A58: S057 | B58: Mechanical | C58: 7.3 | D58: No | E58: ANSYS | F58: Not Placed | G58: 0 | H58: NA | I58: NA | J58: S057 | K58: =IF(tblPlacement[Placement_Status]="Placed",1,0) -> 0 | L58: =IF(tblPlacement[CGPA]>=9,"9+", IF(tblPlacement[CGPA]>=8,"8-9",IF(tblPlacement[CGPA]>=7,"7-8","Below 7"))) -> 7-8 | M58: =IF(tblPlacement[Package_LPA]>=15,"High",IF(tblPlacement[Package_LPA]>=8,"Medium","Low")) -> Low | N58: =IF(tblPlacement[Internship]="Yes",1,0) -> 0
... A501: S500 | B501: ECE | C501: 9.2 | D501: Yes | E501: Embedded Systems | F501: Placed | G501: 15.3 | H501: Samsung | I501: Electronics | J501: S500 | K501: =IF(tblPlacement[Placement_Status]="Placed",1,0) -> 1 | L501: =IF(tblPlacement[CGPA]>=9,"9+", IF(tblPlacement[CGPA]>=8,"8-9",IF(tblPlacement[CGPA]>=7,"7-8","Below 7"))) -> 9+ | M501: =IF(tblPlacement[Package_LPA]>=15,"High",IF(tblPlacement[Package_LPA]>=8,"Medium","Low")) -> High | N501: =IF(tblPlacement[Internship]="Yes",1,0) -> 1

Sheet KPI_Calculations
A1: Total Students | B1: =COUNTA(tblPlacement[Student_ID]) -> 500
A2: Total Placed | B2: =COUNTIF(result[Placement Indicator],1) -> 325 | C2: =COUNTIF(tblPlacement[Placement_Status],"Placed") -> 325
A3: Placement% | B3: =B2/B1 -> 0.65
A4: Average Package | B4: =AVERAGE(tblPlacement[Package_LPA]) -> 7.8998
A5: Highest Package | B5: =MAX(tblPlacement[Package_LPA]) -> 24.4
A6: Total Recruiters | B6: =COUNTA(Placement_Data!P2:P46) -> 45

Sheet Data_Dictionary
A1: Column | B1: Description
A2: Student_ID | B2: Unique student identifier
A3: Branch | B3: Engineering or management branch
A4: CGPA | B4: Academic score out of 10
A5: Internship | B5: Whether student completed an internship
A6: Skill | B6: Primary skill or specialization
A7: Placement_Status | B7: Placed or Not Placed
A8: Package_LPA | B8: Annual package in LPA
A9: Company | B9: Recruiting company
A10: Industry | B10: Industry of recruiter

Sheet Insights
A1: Findings From the Analysis of Placement Data
A3: 1. CSE students achieved the highest placement rate.
A4: 2. Internship improved placement outcomes.
A5: 3. Data Analytics and Machine Learning skills had better packages.
A6: 4. IT and Electronics industries hired the most students.
A7: 5. Students with CGPA above 8 had stronger placement results.
